Workbook

Sheet Données chiffrées par commune
B1: Région | C1: COMMUNE | D1: Zone DR | E1: EQL S35_2026 | F1: Raccordés S35_2026 | G1: Taux de pénétration S35_2026 | H1: EQL S36_2026 | I1: Raccordés S36_2026 | J1: Taux de pénétration S36_2026 | K1: Taux d'évolution taux de pénétration entre S36_2026 et S35_2026 | L1: Évolution (S36 - S35) | M1: Tendance Evolution | N1: Statut Semaine | O1: Nouveaux Raccordés (S36-S35) | P1: Potentiel Non Capté (EQL-Raccordés) | Q1: Segment Pénétration
B2: Tambacounda | C2: Bakel | D2: DRSE | E2: 1864 | F2: 1041 | G2: =F2/E2 -> 0.55847639 | H2: 1864 | I2: 1059 | J2: =I2/H2 -> 0.56813305 | K2: =(J2-G2)/G2 -> 0.017291066 | L2: =J2-G2 -> 0.0096566524 | M2: =IF(L2="","➡️ Stable",IF(L2>0.005,"⬆️ En hausse",IF(L2<-0.005,"⬇️ En baisse","➡️ Stable"))) -> ⬆️ En hausse | N2: =IF(L2>0.005,"🟢 Progression",IF(L2<-0.005,"🔴 Régression","🟡 Stable")) -> 🟢 Progression | O2: =I2-F2 -> 18 | P2: =H2-I2 -> 805 | Q2: =IF(J2="","N/A",IF(J2>=0.7,"🟢 Excellent (≥70%)",IF(J2>=0.55,"🟡 Correct (55-70%)",IF(J2>=0.4,"🟠 Faible (40-55%)","🔴 Critique (<40%)")))) -> 🟡 Correct (55-70%)
B3: Dakar | C3: Bambilor | D3: DR2 | E3: 5400 | F3: 3745 | G3: =F3/E3 -> 0.69351852 | H3: 5400 | I3: 3757 | J3: =I3/H3 -> 0.69574074 | K3: =(J3-G3)/G3 -> 0.0032042724 | L3: =J3-G3 -> 0.0022222222 | M3: =IF(L3="","➡️ Stable",IF(L3>0.005,"⬆️ En hausse",IF(L3<-0.005,"⬇️ En baisse","➡️ Stable"))) -> ➡️ Stable | N3: =IF(L3>0.005,"🟢 Progression",IF(L3<-0.005,"🔴 Régression","🟡 Stable")) -> 🟡 Stable | O3: =I3-F3 -> 12 | P3: =H3-I3 -> 1643 | Q3: =IF(J3="","N/A",IF(J3>=0.7,"🟢 Excellent (≥70%)",IF(J3>=0.55,"🟡 Correct (55-70%)",IF(J3>=0.4,"🟠 Faible (40-55%)","🔴 Critique (<40%)")))) -> 🟡 Correct (55-70%)
B4: Dakar | C4: Bargny | D4: DR2 | E4: 6624 | F4: 4142 | G4: =F4/E4 -> 0.62530193 | H4: 6624 | I4: 4179 | J4: =I4/H4 -> 0.63088768 | K4: =(J4-G4)/G4 -> 0.0089328827 | L4: =J4-G4 -> 0.0055857488 | M4: =IF(L4="","➡️ Stable",IF(L4>0.005,"⬆️ En hausse",IF(L4<-0.005,"⬇️ En baisse","➡️ Stable"))) -> ⬆️ En hausse | N4: =IF(L4>0.005,"🟢 Progression",IF(L4<-0.005,"🔴 Régression","🟡 Stable")) -> 🟢 Progression | O4: =I4-F4 -> 37 | P4: =H4-I4 -> 2445 | Q4: =IF(J4="","N/A",IF(J4>=0.7,"🟢 Excellent (≥70%)",IF(J4>=0.55,"🟡 Correct (55-70%)",IF(J4>=0.4,"🟠 Faible (40-55%)","🔴 Critique (<40%)")))) -> 🟡 Correct (55-70%)
A5: Communes officielles | B5: Ziguinchor | C5: Bignona | D5: DRS | E5: 3766 | F5: 1955 | G5: =F5/E5 -> 0.51911843 | H5: 3766 | I5: 1961 | J5: =I5/H5 -> 0.52071163 | K5: =(J5-G5)/G5 -> 0.0030690537 | L5: =J5-G5 -> 0.0015932023 | M5: =IF(L5="","➡️ Stable",IF(L5>0.005,"⬆️ En hausse",IF(L5<-0.005,"⬇️ En baisse","➡️ Stable"))) -> ➡️ Stable | N5: =IF(L5>0.005,"🟢 Progression",IF(L5<-0.005,"🔴 Régression","🟡 Stable")) -> 🟡 Stable | O5: =I5-F5 -> 6 | P5: =H5-I5 -> 1805 | Q5: =IF(J5="","N/A",IF(J5>=0.7,"🟢 Excellent (≥70%)",IF(J5>=0.55,"🟡 Correct (55-70%)",IF(J5>=0.4,"🟠 Faible (40-55%)","🔴 Critique (<40%)")))) -> 🟠 Faible (40-55%)
B6: Dakar | C6: Biscuiterie | D6: DR1 | E6: 6824 | F6: 4958 | G6: =F6/E6 -> 0.72655334 | H6: 6836 | I6: 4957 | J6: =I6/H6 -> 0.72513166 | K6: =(J6-G6)/G6 -> -0.0019567527 | L6: =J6-G6 -> -0.0014216852 | M6: =IF(L6="","➡️ Stable",IF(L6>0.005,"⬆️ En hausse",IF(L6<-0.005,"⬇️ En baisse","➡️ Stable"))) -> ➡️ Stable | N6: =IF(L6>0.005,"🟢 Progression",IF(L6<-0.005,"🔴 Régression","🟡 Stable")) -> 🟡 Stable | O6: =I6-F6 -> -1 | P6: =H6-I6 -> 1879 | Q6: =IF(J6="","N/A",IF(J6>=0.7,"🟢 Excellent (≥70%)",IF(J6>=0.55,"🟡 Correct (55-70%)",IF(J6>=0.4,"🟠 Faible (40-55%)","🔴 Critique (<40%)")))) -> 🟢 Excellent (≥70%)
B7: Dakar | C7: Cambérène | D7: DR2 | E7: 9766 | F7: 7014 | G7: =F7/E7 -> 0.71820602 | H7: 9766 | I7: 7049 | J7: =I7/H7 -> 0.72178988 | K7: =(J7-G7)/G7 -> 0.00499002 | L7: =J7-G7 -> 0.0035838624 | M7: =IF(L7="","➡️ Stable",IF(L7>0.005,"⬆️ En hausse",IF(L7<-0.005,"⬇️ En baisse","➡️ Stable"))) -> ➡️ Stable | N7: =IF(L7>0.005,"🟢 Progression",IF(L7<-0.005,"🔴 Régression","🟡 Stable")) -> 🟡 Stable | O7: =I7-F7 -> 35 | P7: =H7-I7 -> 2717 | Q7: =IF(J7="","N/A",IF(J7>=0.7,"🟢 Excellent (≥70%)",IF(J7>=0.55,"🟡 Correct (55-70%)",IF(J7>=0.4,"🟠 Faible (40-55%)","🔴 Critique (<40%)")))) -> 🟢 Excellent (≥70%)
B8: Thiès | C8: Chérif Lo | D8: DRC | E8: 2984 | F8: 1241 | G8: =F8/E8 -> 0.41588472 | H8: 2984 | I8: 1271 | J8: =I8/H8 -> 0.42593834 | K8: =(J8-G8)/G8 -> 0.024174053 | L8: =J8-G8 -> 0.010053619 | M8: =IF(L8="","➡️ Stable",IF(L8>0.005,"⬆️ En hausse",IF(L8<-0.005,"⬇️ En baisse","➡️ Stable"))) -> ⬆️ En hausse | N8: =IF(L8>0.005,"🟢 Progression",IF(L8<-0.005,"🔴 Régression","🟡 Stable")) -> 🟢 Progression | O8: =I8-F8 -> 30 | P8: =H8-I8 -> 1713 | Q8: =IF(J8="","N/A",IF(J8>=0.7,"🟢 Excellent (≥70%)",IF(J8>=0.55,"🟡 Correct (55-70%)",IF(J8>=0.4,"🟠 Faible (40-55%)","🔴 Critique (<40%)")))) -> 🟠 Faible (40-55%)
B9: Louga | C9: Dahra | D9: DRN | E9: 696 | F9: 558 | G9: =F9/E9 -> 0.80172414 | H9: 696 | I9: 563 | J9: =I9/H9 -> 0.80890805 | K9: =(J9-G9)/G9 -> 0.0089605735 | L9: =J9-G9 -> 0.007183908 | M9: =IF(L9="","➡️ Stable",IF(L9>0.005,"⬆️ En hausse",IF(L9<-0.005,"⬇️ En baisse","➡️ Stable"))) -> ⬆️ En hausse | N9: =IF(L9>0.005,"🟢 Progression",IF(L9<-0.005,"🔴 Régression","🟡 Stable")) -> 🟢 Progression | O9: =I9-F9 -> 5 | P9: =H9-I9 -> 133 | Q9: =IF(J9="","N/A",IF(J9>=0.7,"🟢 Excellent (≥70%)",IF(J9>=0.55,"🟡 Correct (55-70%)",IF(J9>=0.4,"🟠 Faible (40-55%)","🔴 Critique (<40%)")))) -> 🟢 Excellent (≥70%)
B10: Dakar | C10: Dakar-Plateau | D10: DR1 | E10: 26994 | F10: 11547 | G10: =F10/E10 -> 0.42776172 | H10: 27024 | I10: 11546 | J10: =I10/H10 -> 0.42724985 | K10: =(J10-G10)/G10 -> -0.0011966308 | L10: =J10-G10 -> -0.00051187284 | M10: =IF(L10="","➡️ Stable",IF(L10>0.005,"⬆️ En hausse",IF(L10<-0.005,"⬇️ En baisse","➡️ Stable"))) -> ➡️ Stable | N10: =IF(L10>0.005,"🟢 Progression",IF(L10<-0.005,"🔴 Régression","🟡 Stable")) -> 🟡 Stable | O10: =I10-F10 -> -1 | P10: =H10-I10 -> 15478 | Q10: =IF(J10="","N/A",IF(J10>=0.7,"🟢 Excellent (≥70%)",IF(J10>=0.55,"🟡 Correct (55-70%)",IF(J10>=0.4,"🟠 Faible (40-55%)","🔴 Critique (<40%)")))) -> 🟠 Faible (40-55%)
B11: Dakar | C11: Dalifort | D11: DR1 | E11: 5054 | F11: 3180 | G11: =F11/E11 -> 0.62920459 | H11: 5054 | I11: 3194 | J11: =I11/H11 -> 0.63197467 | K11: =(J11-G11)/G11 -> 0.0044025157 | L11: =J11-G11 -> 0.0027700831 | M11: =IF(L11="","➡️ Stable",IF(L11>0.005,"⬆️ En hausse",IF(L11<-0.005,"⬇️ En baisse","➡️ Stable"))) -> ➡️ Stable | N11: =IF(L11>0.005,"🟢 Progression",IF(L11<-0.005,"🔴 Régression","🟡 Stable")) -> 🟡 Stable | O11: =I11-F11 -> 14 | P11: =H11-I11 -> 1860 | Q11: =IF(J11="","N/A",IF(J11>=0.7,"🟢 Excellent (≥70%)",IF(J11>=0.55,"🟡 Correct (55-70%)",IF(J11>=0.4,"🟠 Faible (40-55%)","🔴 Critique (<40%)")))) -> 🟡 Correct (55-70%)
B12: Louga | C12: Darou Mousty | D12: DRT | E12: 1032 | F12: 652 | G12: =F12/E12 -> 0.63178295 | H12: 1032 | I12: 653 | J12: =I12/H12 -> 0.63275194 | K12: =(J12-G12)/G12 -> 0.0015337423 | L12: =J12-G12 -> 0.00096899225 | M12: =IF(L12="","➡️ Stable",IF(L12>0.005,"⬆️ En hausse",IF(L12<-0.005,"⬇️ En baisse","➡️ Stable"))) -> ➡️ Stable | N12: =IF(L12>0.005,"🟢 Progression",IF(L12<-0.005,"🔴 Régression","🟡 Stable")) -> 🟡 Stable | O12: =I12-F12 -> 1 | P12: =H12-I12 -> 379 | Q12: =IF(J12="","N/A",IF(J12>=0.7,"🟢 Excellent (≥70%)",IF(J12>=0.55,"🟡 Correct (55-70%)",IF(J12>=0.4,"🟠 Faible (40-55%)","🔴 Critique (<40%)")))) -> 🟡 Correct (55-70%)
B13: Dakar | C13: Diamaguène-Sicap Mbao | D13: DR2 | E13: 9073 | F13: 5944 | G13: =F13/E13 -> 0.65513061 | H13: 9073 | I13: 5962 | J13: =I13/H13 -> 0.65711452 | K13: =(J13-G13)/G13 -> 0.0030282638 | L13: =J13-G13 -> 0.0019839083 | M13: =IF(L13="","➡️ Stable",IF(L13>0.005,"⬆️ En hausse",IF(L13<-0.005,"⬇️ En baisse","➡️ Stable"))) -> ➡️ Stable | N13: =IF(L13>0.005,"🟢 Progression",IF(L13<-0.005,"🔴 Régression","🟡 Stable")) -> 🟡 Stable | O13: =I13-F13 -> 18 | P13: =H13-I13 -> 3111 | Q13: =IF(J13="","N/A",IF(J13>=0.7,"🟢 Excellent (≥70%)",IF(J13>=0.55,"🟡 Correct (55-70%)",IF(J13>=0.4,"🟠 Faible (40-55%)","🔴 Critique (<40%)")))) -> 🟡 Correct (55-70%)
B14: Dakar | C14: Diamniadio | D14: DR2 | E14: 8310 | F14: 4526 | G14: =F14/E14 -> 0.54464501 | H14: 8310 | I14: 4576 | J14: =I14/H14 -> 0.55066185 | K14: =(J14-G14)/G14 -> 0.011047282 | L14: =J14-G14 -> 0.0060168472 | M14: =IF(L14="","➡️ Stable",IF(L14>0.005,"⬆️ En hausse",IF(L14<-0.005,"⬇️ En baisse","➡️ Stable"))) -> ⬆️ En hausse | N14: =IF(L14>0.005,"🟢 Progression",IF(L14<-0.005,"🔴 Régression","🟡 Stable")) -> 🟢 Progression | O14: =I14-F14 -> 50 | P14: =H14-I14 -> 3734 | Q14: =IF(J14="","N/A",IF(J14>=0.7,"🟢 Excellent (≥70%)",IF(J14>=0.55,"🟡 Correct (55-70%)",IF(J14>=0.4,"🟠 Faible (40-55%)","🔴 Critique (<40%)")))) -> 🟡 Correct (55-70%)
B15: Ziguinchor | C15: Diembéring | D15: DRS | E15: 2516 | F15: 1364 | G15: =F15/E15 -> 0.54213037 | H15: 2524 | I15: 1372 | J15: =I15/H15 -> 0.54358162 | K15: =(J15-G15)/G15 -> 0.0026769407 | L15: =J15-G15 -> 0.0014512508 | M15: =IF(L15="","➡️ Stable",IF(L15>0.005,"⬆️ En hausse",IF(L15<-0.005,"⬇️ En baisse","➡️ Stable"))) -> ➡️ Stable | N15: =IF(L15>0.005,"🟢 Progression",IF(L15<-0.005,"🔴 Régression","🟡 Stable")) -> 🟡 Stable | O15: =I15-F15 -> 8 | P15: =H15-I15 -> 1152 | Q15: =IF(J15="","N/A",IF(J15>=0.7,"🟢 Excellent (≥70%)",IF(J15>=0.55,"🟡 Correct (55-70%)",IF(J15>=0.4,"🟠 Faible (40-55%)","🔴 Critique (<40%)")))) -> 🟠 Faible (40-55%)
B16: Dakar | C16: Dieuppeul-Derklé | D16: DR1 | E16: 10548 | F16: 7013 | G16: =F16/E16 -> 0.66486538 | H16: 10548 | I16: 7000 | J16: =I16/H16 -> 0.66363292 | K16: =(J16-G16)/G16 -> -0.0018537003 | L16: =J16-G16 -> -0.0012324611 | M16: =IF(L16="","➡️ Stable",IF(L16>0.005,"⬆️ En hausse",IF(L16<-0.005,"⬇️ En baisse","➡️ Stable"))) -> ➡️ Stable | N16: =IF(L16>0.005,"🟢 Progression",IF(L16<-0.005,"🔴 Régression","🟡 Stable")) -> 🟡 Stable | O16: =I16-F16 -> -13 | P16: =H16-I16 -> 3548 | Q16: =IF(J16="","N/A",IF(J16>=0.7,"🟢 Excellent (≥70%)",IF(J16>=0.55,"🟡 Correct (55-70%)",IF(J16>=0.4,"🟠 Faible (40-55%)","🔴 Critique (<40%)")))) -> 🟡 Correct (55-70%)
B17: Kolda | C17: Dioulacolon | D17: DRS | E17: 1136 | F17: 539 | G17: =F17/E17 -> 0.47447183 | H17: 1136 | I17: 543 | J17: =I17/H17 -> 0.47799296 | K17: =(J17-G17)/G17 -> 0.0074211503 | L17: =J17-G17 -> 0.0035211268 | M17: =IF(L17="","➡️ Stable",IF(L17>0.005,"⬆️ En hausse",IF(L17<-0.005,"⬇️ En baisse","➡️ Stable"))) -> ➡️ Stable | N17: =IF(L17>0.005,"🟢 Progression",IF(L17<-0.005,"🔴 Régression","🟡 Stable")) -> 🟡 Stable | O17: =I17-F17 -> 4 | P17: =H17-I17 -> 593 | Q17: =IF(J17="","N/A",IF(J17>=0.7,"🟢 Excellent (≥70%)",IF(J17>=0.55,"🟡 Correct (55-70%)",IF(J17>=0.4,"🟠 Faible (40-55%)","🔴 Critique (<40%)")))) -> 🟠 Faible (40-55%)
... B115: Thiès | C115: NGUEKHOKH | D115: DRC | E115: 2456 | F115: 0 | G115: =F115/E115 -> 0 | H115: 4992 | I115: 398 | J115: =I115/H115 -> 0.079727564 | K115: =(J115-G115)/G115 -> #DIV/0! | L115: =J115-G115 -> 0.079727564 | M115: =IF(L115="","➡️ Stable",IF(L115>0.005,"⬆️ En hausse",IF(L115<-0.005,"⬇️ En baisse","➡️ Stable"))) -> ⬆️ En hausse | N115: =IF(L115>0.005,"🟢 Progression",IF(L115<-0.005,"🔴 Régression","🟡 Stable")) -> 🟢 Progression | O115: =I115-F115 -> 398 | P115: =H115-I115 -> 4594 | Q115: =IF(J115="","N/A",IF(J115>=0.7,"🟢 Excellent (≥70%)",IF(J115>=0.55,"🟡 Correct (55-70%)",IF(J115>=0.4,"🟠 Faible (40-55%)","🔴 Critique (<40%)")))) -> 🔴 Critique (<40%)

Sheet Données chiffrées par plaque
A1: PLAQUE | B1: Zone DR | C1: EQL PLAQUES | D1: Total FO occupées | E1: TAUX D'OCCUPATION | F1: Total PBO déployé | G1: Total_PBO saturé | H1: Taux de PBO saturé | I1: Statut PBO saturé | J1: Date ouverture | K1: ZONES | L1: Commune | M1: Arrondissement | N1: Département | O1: Région | P1: Âge plaque (mois) | Q1: Tranche ancienneté
A2: O_MED_A03 | B2: DR1 | C2: 1736 | D2: 614 | E2: 0.35368664 | F2: 154 | G2: 54 | H2: 0.3506 | I2: =IF(H2="","N/A", IF(H2>=80%,"🔴 Saturé (≥80%)", IF(H2>=40%,"🟡 Attention (40-80%)", "🟢 Non saturé (<40%)" ) ) ) -> 🟢 Non saturé (<40%) | J2: 43045 | K2: Plateau | L2: Dakar-Plateau | M2: Dakar-Plateau | N2: Dakar | O2: Dakar | P2: =IF(J2="","",ROUND((TODAY()-J2)/30.44,0)) -> 106 | Q2: =IF(P2="","N/A",IF(P2<6,"🆕 < 6 mois",IF(P2<12,"📅 6-12 mois",IF(P2<24,"📆 1-2 ans","🗓️ > 2 ans")))) -> 🗓️ > 2 ans
A3: O_SVD_C10 | B3: DR1 | C3: 3830 | D3: 1764 | E3: 0.46057441 | F3: 335 | G3: 100 | H3: 0.2985 | I3: =IF(H3="","N/A", IF(H3>=80%,"🔴 Saturé (≥80%)", IF(H3>=40%,"🟡 Attention (40-80%)", "🟢 Non saturé (<40%)" ) ) ) -> 🟢 Non saturé (<40%) | J3: 43045 | K3: Keur Gorgui, Sacré Cœur pyrotechnie | L3: Mermoz-Sacré-Cœur | M3: Almadies | N3: Dakar | O3: Dakar | P3: =IF(J3="","",ROUND((TODAY()-J3)/30.44,0)) -> 106 | Q3: =IF(P3="","N/A",IF(P3<6,"🆕 < 6 mois",IF(P3<12,"📅 6-12 mois",IF(P3<24,"📆 1-2 ans","🗓️ > 2 ans")))) -> 🗓️ > 2 ans
A4: O_REP_A04 | B4: DR1 | C4: 268 | D4: 95 | E4: 0.35447761 | F4: 26 | G4: 2 | H4: 0.0769 | I4: =IF(H4="","N/A", IF(H4>=80%,"🔴 Saturé (≥80%)", IF(H4>=40%,"🟡 Attention (40-80%)", "🟢 Non saturé (<40%)" ) ) ) -> 🟢 Non saturé (<40%) | J4: 43045 | K4: Plateau | L4: Dakar-Plateau | M4: Dakar-Plateau | N4: Dakar | O4: Dakar | P4: =IF(J4="","",ROUND((TODAY()-J4)/30.44,0)) -> 106 | Q4: =IF(P4="","N/A",IF(P4<6,"🆕 < 6 mois",IF(P4<12,"📅 6-12 mois",IF(P4<24,"📆 1-2 ans","🗓️ > 2 ans")))) -> 🗓️ > 2 ans
A5: O_REP_B15 | B5: DR1 | C5: 808 | D5: 323 | E5: 0.39975248 | F5: 68 | G5: 10 | H5: 0.1471 | I5: =IF(H5="","N/A", IF(H5>=80%,"🔴 Saturé (≥80%)", IF(H5>=40%,"🟡 Attention (40-80%)", "🟢 Non saturé (<40%)" ) ) ) -> 🟢 Non saturé (<40%) | J5: 43046 | K5: Plateau | L5: Dakar-Plateau | M5: Dakar-Plateau | N5: Dakar | O5: Dakar | P5: =IF(J5="","",ROUND((TODAY()-J5)/30.44,0)) -> 106 | Q5: =IF(P5="","N/A",IF(P5<6,"🆕 < 6 mois",IF(P5<12,"📅 6-12 mois",IF(P5<24,"📆 1-2 ans","🗓️ > 2 ans")))) -> 🗓️ > 2 ans
A6: O_REP_A11 | B6: DR1 | C6: 666 | D6: 243 | E6: 0.36486486 | F6: 46 | G6: 5 | H6: 0.1087 | I6: =IF(H6="","N/A", IF(H6>=80%,"🔴 Saturé (≥80%)", IF(H6>=40%,"🟡 Attention (40-80%)", "🟢 Non saturé (<40%)" ) ) ) -> 🟢 Non saturé (<40%) | J6: 43046 | K6: Plateau | L6: Dakar-Plateau | M6: Dakar-Plateau | N6: Dakar | O6: Dakar | P6: =IF(J6="","",ROUND((TODAY()-J6)/30.44,0)) -> 106 | Q6: =IF(P6="","N/A",IF(P6<6,"🆕 < 6 mois",IF(P6<12,"📅 6-12 mois",IF(P6<24,"📆 1-2 ans","🗓️ > 2 ans")))) -> 🗓️ > 2 ans
A7: O_REP_A12 | B7: DR1 | C7: 476 | D7: 162 | E7: 0.34033613 | F7: 30 | G7: 2 | H7: 0.0667 | I7: =IF(H7="","N/A", IF(H7>=80%,"🔴 Saturé (≥80%)", IF(H7>=40%,"🟡 Attention (40-80%)", "🟢 Non saturé (<40%)" ) ) ) -> 🟢 Non saturé (<40%) | J7: 43046 | K7: Plateau | L7: Dakar-Plateau | M7: Dakar-Plateau | N7: Dakar | O7: Dakar | P7: =IF(J7="","",ROUND((TODAY()-J7)/30.44,0)) -> 106 | Q7: =IF(P7="","N/A",IF(P7<6,"🆕 < 6 mois",IF(P7<12,"📅 6-12 mois",IF(P7<24,"📆 1-2 ans","🗓️ > 2 ans")))) -> 🗓️ > 2 ans
A8: O_REP_B17 | B8: DR1 | C8: 760 | D8: 349 | E8: 0.45921053 | F8: 64 | G8: 18 | H8: 0.2812 | I8: =IF(H8="","N/A", IF(H8>=80%,"🔴 Saturé (≥80%)", IF(H8>=40%,"🟡 Attention (40-80%)", "🟢 Non saturé (<40%)" ) ) ) -> 🟢 Non saturé (<40%) | J8: 43053 | K8: Plateau | L8: Dakar-Plateau | M8: Dakar-Plateau | N8: Dakar | O8: Dakar | P8: =IF(J8="","",ROUND((TODAY()-J8)/30.44,0)) -> 106 | Q8: =IF(P8="","N/A",IF(P8<6,"🆕 < 6 mois",IF(P8<12,"📅 6-12 mois",IF(P8<24,"📆 1-2 ans","🗓️ > 2 ans")))) -> 🗓️ > 2 ans
A9: O_REP_A09 | B9: DR1 | C9: 1340 | D9: 597 | E9: 0.44552239 | F9: 134 | G9: 24 | H9: 0.1791 | I9: =IF(H9="","N/A", IF(H9>=80%,"🔴 Saturé (≥80%)", IF(H9>=40%,"🟡 Attention (40-80%)", "🟢 Non saturé (<40%)" ) ) ) -> 🟢 Non saturé (<40%) | J9: 43053 | K9: Plateau | L9: Dakar-Plateau | M9: Dakar-Plateau | N9: Dakar | O9: Dakar | P9: =IF(J9="","",ROUND((TODAY()-J9)/30.44,0)) -> 106 | Q9: =IF(P9="","N/A",IF(P9<6,"🆕 < 6 mois",IF(P9<12,"📅 6-12 mois",IF(P9<24,"📆 1-2 ans","🗓️ > 2 ans")))) -> 🗓️ > 2 ans
A10: O_REP_A05 | B10: DR1 | C10: 850 | D10: 345 | E10: 0.40588235 | F10: 85 | G10: 20 | H10: 0.2353 | I10: =IF(H10="","N/A", IF(H10>=80%,"🔴 Saturé (≥80%)", IF(H10>=40%,"🟡 Attention (40-80%)", "🟢 Non saturé (<40%)" ) ) ) -> 🟢 Non saturé (<40%) | J10: 43059 | K10: Plateau | L10: Dakar-Plateau | M10: Dakar-Plateau | N10: Dakar | O10: Dakar | P10: =IF(J10="","",ROUND((TODAY()-J10)/30.44,0)) -> 106 | Q10: =IF(P10="","N/A",IF(P10<6,"🆕 < 6 mois",IF(P10<12,"📅 6-12 mois",IF(P10<24,"📆 1-2 ans","🗓️ > 2 ans")))) -> 🗓️ > 2 ans
A11: O_REP_A02 | B11: DR1 | C11: 1124 | D11: 564 | E11: 0.50177936 | F11: 118 | G11: 26 | H11: 0.2203 | I11: =IF(H11="","N/A", IF(H11>=80%,"🔴 Saturé (≥80%)", IF(H11>=40%,"🟡 Attention (40-80%)", "🟢 Non saturé (<40%)" ) ) ) -> 🟢 Non saturé (<40%) | J11: 43074 | K11: Plateau | L11: Dakar-Plateau | M11: Dakar-Plateau | N11: Dakar | O11: Dakar | P11: =IF(J11="","",ROUND((TODAY()-J11)/30.44,0)) -> 105 | Q11: =IF(P11="","N/A",IF(P11<6,"🆕 < 6 mois",IF(P11<12,"📅 6-12 mois",IF(P11<24,"📆 1-2 ans","🗓️ > 2 ans")))) -> 🗓️ > 2 ans
A12: O_REP_A08 | B12: DR1 | C12: 1348 | D12: 487 | E12: 0.36127596 | F12: 87 | G12: 15 | H12: 0.1724 | I12: =IF(H12="","N/A", IF(H12>=80%,"🔴 Saturé (≥80%)", IF(H12>=40%,"🟡 Attention (40-80%)", "🟢 Non saturé (<40%)" ) ) ) -> 🟢 Non saturé (<40%) | J12: 43095 | K12: Plateau | L12: Dakar-Plateau | M12: Dakar-Plateau | N12: Dakar | O12: Dakar | P12: =IF(J12="","",ROUND((TODAY()-J12)/30.44,0)) -> 104 | Q12: =IF(P12="","N/A",IF(P12<6,"🆕 < 6 mois",IF(P12<12,"📅 6-12 mois",IF(P12<24,"📆 1-2 ans","🗓️ > 2 ans")))) -> 🗓️ > 2 ans
A13: O_REP_A10 | B13: DR1 | C13: 320 | D13: 71 | E13: 0.221875 | F13: 29 | G13: 3 | H13: 0.1034 | I13: =IF(H13="","N/A", IF(H13>=80%,"🔴 Saturé (≥80%)", IF(H13>=40%,"🟡 Attention (40-80%)", "🟢 Non saturé (<40%)" ) ) ) -> 🟢 Non saturé (<40%) | J13: 43096 | K13: Plateau | L13: Dakar-Plateau | M13: Dakar-Plateau | N13: Dakar | O13: Dakar | P13: =IF(J13="","",ROUND((TODAY()-J13)/30.44,0)) -> 104 | Q13: =IF(P13="","N/A",IF(P13<6,"🆕 < 6 mois",IF(P13<12,"📅 6-12 mois",IF(P13<24,"📆 1-2 ans","🗓️ > 2 ans")))) -> 🗓️ > 2 ans
... A483: O_KMR_L40 | B483: DR2 | C483: 1068 | D483: 684 | E483: 0.64044944 | F483: 178 | G483: 82 | H483: 0.4607 | I483: =IF(H483="","N/A", IF(H483>=80%,"🔴 Saturé (≥80%)", IF(H483>=40%,"🟡 Attention (40-80%)", "🟢 Non saturé (<40%)" ) ) ) -> 🟡 Attention (40-80%) | J483: 44582 | K483: Keur Massar | L483: Keur Massar Nord | M483: Malika | N483: Keur Massar | O483: Dakar | P483: =IF(J483="","",ROUND((TODAY()-J483)/30.44,0)) -> 56 | Q483: =IF(P483="","N/A",IF(P483<6,"🆕 < 6 mois",IF(P483<12,"📅 6-12 mois",IF(P483<24,"📆 1-2 ans","🗓️ > 2 ans")))) -> 🗓️ > 2 ans
A484: O_GDW_M15 | B484: DR2 | C484: 792 | D484: 510 | E484: 0.64393939 | F484: 131 | G484: 62 | H484: 0.4733 | I484: =IF(H484="","N/A", IF(H484>=80%,"🔴 Saturé (≥80%)", IF(H484>=40%,"🟡 Attention (40-80%)", "🟢 Non saturé (<40%)" ) ) ) -> 🟡 Attention (40-80%) | J484: 44591 | K484: 0 | L484: Golf Sud | M484: Guediawaye | N484: Guédiawaye | O484: Dakar | P484: =IF(J484="","",ROUND((TODAY()-J484)/30.44,0)) -> 55 | Q484: =IF(P484="","N/A",IF(P484<6,"🆕 < 6 mois",IF(P484<12,"📅 6-12 mois",IF(P484<24,"📆 1-2 ans","🗓️ > 2 ans")))) -> 🗓️ > 2 ans
A485: O_THS_A10 | B485: DRC | C485: 1430 | D485: 833 | E485: 0.58251748 | F485: 238 | G485: 108 | H485: 0.4538 | I485: =IF(H485="","N/A", IF(H485>=80%,"🔴 Saturé (≥80%)", IF(H485>=40%,"🟡 Attention (40-80%)", "🟢 Non saturé (<40%)" ) ) ) -> 🟡 Attention (40-80%) | J485: 44591 | K485: Thies Nguinth | L485: Thiès Nord | M485: Thies Nord | N485: Thiès | O485: Thiès | P485: =IF(J485="","",ROUND((TODAY()-J485)/30.44,0)) -> 55 | Q485: =IF(P485="","N/A",IF(P485<6,"🆕 < 6 mois",IF(P485<12,"📅 6-12 mois",IF(P485<24,"📆 1-2 ans","🗓️ > 2 ans")))) -> 🗓️ > 2 ans
A486: O_TIV_A07 | B486: DRC | C486: 452 | D486: 271 | E486: 0.59955752 | F486: 75 | G486: 40 | H486: 0.5333 | I486: =IF(H486="","N/A", IF(H486>=80%,"🔴 Saturé (≥80%)", IF(H486>=40%,"🟡 Attention (40-80%)", "🟢 Non saturé (<40%)" ) ) ) -> 🟡 Attention (40-80%) | J486: 44591 | K486: Quartier derriere EDK | L486: Tivaouane | M486: Pambal | N486: Tivaouane | O486: Thiès | P486: =IF(J486="","",ROUND((TODAY()-J486)/30.44,0)) -> 55 | Q486: =IF(P486="","N/A",IF(P486<6,"🆕 < 6 mois",IF(P486<12,"📅 6-12 mois",IF(P486<24,"📆 1-2 ans","🗓️ > 2 ans")))) -> 🗓️ > 2 ans
A487: O_THS_A09 | B487: DRC | C487: 590 | D487: 443 | E487: 0.75084746 | F487: 98 | G487: 67 | H487: 0.6837 | I487: =IF(H487="","N/A", IF(H487>=80%,"🔴 Saturé (≥80%)", IF(H487>=40%,"🟡 Attention (40-80%)", "🟢 Non saturé (<40%)" ) ) ) -> 🟡 Attention (40-80%) | J487: 44591 | K487: Fahu | L487: Fandène | M487: Keur Moussa | N487: Thiès | O487: Thiès | P487: =IF(J487="","",ROUND((TODAY()-J487)/30.44,0)) -> 55 | Q487: =IF(P487="","N/A",IF(P487<6,"🆕 < 6 mois",IF(P487<12,"📅 6-12 mois",IF(P487<24,"📆 1-2 ans","🗓️ > 2 ans")))) -> 🗓️ > 2 ans
A488: O_KLK_A19 | B488: DRE | C488: 984 | D488: 545 | E488: 0.55386179 | F488: 164 | G488: 51 | H488: 0.311 | I488: =IF(H488="","N/A", IF(H488>=80%,"🔴 Saturé (≥80%)", IF(H488>=40%,"🟡 Attention (40-80%)", "🟢 Non saturé (<40%)" ) ) ) -> 🟢 Non saturé (<40%) | J488: 44591 | K488: Kahone | L488: Kahone | M488: Kahone | N488: Kaolack | O488: Kaolack | P488: =IF(J488="","",ROUND((TODAY()-J488)/30.44,0)) -> 55 | Q488: =IF(P488="","N/A",IF(P488<6,"🆕 < 6 mois",IF(P488<12,"📅 6-12 mois",IF(P488<24,"📆 1-2 ans","🗓️ > 2 ans")))) -> 🗓️ > 2 ans
A489: O_THS_A31 | B489: DRC | C489: 852 | D489: 556 | E489: 0.65258216 | F489: 142 | G489: 62 | H489: 0.4366 | I489: =IF(H489="","N/A", IF(H489>=80%,"🔴 Saturé (≥80%)", IF(H489>=40%,"🟡 Attention (40-80%)", "🟢 Non saturé (<40%)" ) ) ) -> 🟡 Attention (40-80%) | J489: 44591 | K489: Thies Nguinth | L489: Thiès Nord | M489: Thies Nord | N489: Thiès | O489: Thiès | P489: =IF(J489="","",ROUND((TODAY()-J489)/30.44,0)) -> 55 | Q489: =IF(P489="","N/A",IF(P489<6,"🆕 < 6 mois",IF(P489<12,"📅 6-12 mois",IF(P489<24,"📆 1-2 ans","🗓️ > 2 ans")))) -> 🗓️ > 2 ans
A490: O_DKH_A00 | B490: DRT | C490: 528 | D490: 400 | E490: 0.75757576 | F490: 66 | G490: 41 | H490: 0.6212 | I490: =IF(H490="","N/A", IF(H490>=80%,"🔴 Saturé (≥80%)", IF(H490>=40%,"🟡 Attention (40-80%)", "🟢 Non saturé (<40%)" ) ) ) -> 🟡 Attention (40-80%) | J490: 44622 | K490: Darou Khoudoss 1, Touba Alie 1 | L490: Touba Mosquée | M490: Ndame | N490: Mbacké | O490: Diourbel | P490: =IF(J490="","",ROUND((TODAY()-J490)/30.44,0)) -> 54 | Q490: =IF(P490="","N/A",IF(P490<6,"🆕 < 6 mois",IF(P490<12,"📅 6-12 mois",IF(P490<24,"📆 1-2 ans","🗓️ > 2 ans")))) -> 🗓️ > 2 ans
A491: O_DKH_A15 | B491: DRT | C491: 512 | D491: 339 | E491: 0.66210938 | F491: 64 | G491: 22 | H491: 0.3438 | I491: =IF(H491="","N/A", IF(H491>=80%,"🔴 Saturé (≥80%)", IF(H491>=40%,"🟡 Attention (40-80%)", "🟢 Non saturé (<40%)" ) ) ) -> 🟢 Non saturé (<40%) | J491: 44622 | K491: Darou Khoudoss 5 | L491: Touba Mosquée | M491: Ndame | N491: Mbacké | O491: Diourbel | P491: =IF(J491="","",ROUND((TODAY()-J491)/30.44,0)) -> 54 | Q491: =IF(P491="","N/A",IF(P491<6,"🆕 < 6 mois",IF(P491<12,"📅 6-12 mois",IF(P491<24,"📆 1-2 ans","🗓️ > 2 ans")))) -> 🗓️ > 2 ans
A492: O_TIA_E27 | B492: DR2 | C492: 488 | D492: 379 | E492: 0.77663934 | F492: 61 | G492: 42 | H492: 0.6885 | I492: =IF(H492="","N/A", IF(H492>=80%,"🔴 Saturé (≥80%)", IF(H492>=40%,"🟡 Attention (40-80%)", "🟢 Non saturé (<40%)" ) ) ) -> 🟡 Attention (40-80%) | J492: 44662 | K492: Thiaroye,Sam-Sam4 | L492: Diamaguène-Sicap Mbao | M492: Ville de Pikine | N492: Pikine | O492: Dakar | P492: =IF(J492="","",ROUND((TODAY()-J492)/30.44,0)) -> 53 | Q492: =IF(P492="","N/A",IF(P492<6,"🆕 < 6 mois",IF(P492<12,"📅 6-12 mois",IF(P492<24,"📆 1-2 ans","🗓️ > 2 ans")))) -> 🗓️ > 2 ans
A493: O_KMR_L45 | B493: DR2 | C493: 752 | D493: 564 | E493: 0.75 | F493: 94 | G493: 62 | H493: 0.6596 | I493: =IF(H493="","N/A", IF(H493>=80%,"🔴 Saturé (≥80%)", IF(H493>=40%,"🟡 Attention (40-80%)", "🟢 Non saturé (<40%)" ) ) ) -> 🟡 Attention (40-80%) | J493: 44671 | K493: Keur Massar, Unité 4 | L493: Keur Massar Nord | M493: Malika | N493: Keur Massar | O493: Dakar | P493: =IF(J493="","",ROUND((TODAY()-J493)/30.44,0)) -> 53 | Q493: =IF(P493="","N/A",IF(P493<6,"🆕 < 6 mois",IF(P493<12,"📅 6-12 mois",IF(P493<24,"📆 1-2 ans","🗓️ > 2 ans")))) -> 🗓️ > 2 ans
A494: O_MBR_A06 | B494: DRC | C494: 720 | D494: 512 | E494: 0.71111111 | F494: 90 | G494: 48 | H494: 0.5333 | I494: =IF(H494="","N/A", IF(H494>=80%,"🔴 Saturé (≥80%)", IF(H494>=40%,"🟡 Attention (40-80%)", "🟢 Non saturé (<40%)" ) ) ) -> 🟡 Attention (40-80%) | J494: 44671 | K494: Mbour FH, Warang_Soce | L494: Malicounda | M494: Sindia | N494: Mbour | O494: Thiès | P494: =IF(J494="","",ROUND((TODAY()-J494)/30.44,0)) -> 53 | Q494: =IF(P494="","N/A",IF(P494<6,"🆕 < 6 mois",IF(P494<12,"📅 6-12 mois",IF(P494<24,"📆 1-2 ans","🗓️ > 2 ans")))) -> 🗓️ > 2 ans
A495: O_DKH_A17 | B495: DRT | C495: 456 | D495: 319 | E495: 0.6995614 | F495: 57 | G495: 26 | H495: 0.4561 | I495: =IF(H495="","N/A", IF(H495>=80%,"🔴 Saturé (≥80%)", IF(H495>=40%,"🟡 Attention (40-80%)", "🟢 Non saturé (<40%)" ) ) ) -> 🟡 Attention (40-80%) | J495: 44672 | K495: Touba Guédé | L495: Touba Mosquée | M495: Ndame | N495: Mbacké | O495: Diourbel | P495: =IF(J495="","",ROUND((TODAY()-J495)/30.44,0)) -> 53 | Q495: =IF(P495="","N/A",IF(P495<6,"🆕 < 6 mois",IF(P495<12,"📅 6-12 mois",IF(P495<24,"📆 1-2 ans","🗓️ > 2 ans")))) -> 🗓️ > 2 ans
A496: O_DKH_A16 | B496: DRT | C496: 440 | D496: 314 | E496: 0.71363636 | F496: 55 | G496: 20 | H496: 0.3636 | I496: =IF(H496="","N/A", IF(H496>=80%,"🔴 Saturé (≥80%)", IF(H496>=40%,"🟡 Attention (40-80%)", "🟢 Non saturé (<40%)" ) ) ) -> 🟢 Non saturé (<40%) | J496: 44672 | K496: Darou Khoudoss 1, Touba Alie 1 | L496: Touba Mosquée | M496: Ndame | N496: Mbacké | O496: Diourbel | P496: =IF(J496="","",ROUND((TODAY()-J496)/30.44,0)) -> 53 | Q496: =IF(P496="","N/A",IF(P496<6,"🆕 < 6 mois",IF(P496<12,"📅 6-12 mois",IF(P496<24,"📆 1-2 ans","🗓️ > 2 ans")))) -> 🗓️ > 2 ans
... A534: O_KMR_L05 | B534: DR2 | C534: 624 | D534: 512 | E534: 0.82051282 | F534: 78 | G534: 50 | H534: 0.641 | I534: =IF(H534="","N/A", IF(H534>=80%,"🔴 Saturé (≥80%)", IF(H534>=40%,"🟡 Attention (40-80%)", "🟢 Non saturé (<40%)" ) ) ) -> 🟡 Attention (40-80%) | J534: 44728 | K534: Malika | L534: Yeumbeul Nord | M534: Yeumbeul | N534: Keur Massar | O534: Dakar | P534: =IF(J534="","",ROUND((TODAY()-J534)/30.44,0)) -> 51 | Q534: =IF(P534="","N/A",IF(P534<6,"🆕 < 6 mois",IF(P534<12,"📅 6-12 mois",IF(P534<24,"📆 1-2 ans","🗓️ > 2 ans")))) -> 🗓️ > 2 ans
A535: O_GDW_M16 | B535: DR2 | C535: 600 | D535: 421 | E535: 0.70166667 | F535: 75 | G535: 38 | H535: 0.5067 | I535: =IF(H535="","N/A", IF(H535>=80%,"🔴 Saturé (≥80%)", IF(H535>=40%,"🟡 Attention (40-80%)", "🟢 Non saturé (<40%)" ) ) ) -> 🟡 Attention (40-80%) | J535: 44734 | K535: 0 | L535: Golf Sud | M535: Guediawaye | N535: Guédiawaye | O535: Dakar | P535: =IF(J535="","",ROUND((TODAY()-J535)/30.44,0)) -> 51 | Q535: =IF(P535="","N/A",IF(P535<6,"🆕 < 6 mois",IF(P535<12,"📅 6-12 mois",IF(P535<24,"📆 1-2 ans","🗓️ > 2 ans")))) -> 🗓️ > 2 ans
A536: O_GMB_B27 | B536: DRC | C536: 776 | D536: 430 | E536: 0.55412371 | F536: 97 | G536: 27 | H536: 0.2784 | I536: =IF(H536="","N/A", IF(H536>=80%,"🔴 Saturé (≥80%)", IF(H536>=40%,"🟡 Attention (40-80%)", "🟢 Non saturé (<40%)" ) ) ) -> 🟢 Non saturé (<40%) | J536: 44734 | K536: 0 | L536: Saly Portudal | M536: Sindia | N536: Mbour | O536: Thiès | P536: =IF(J536="","",ROUND((TODAY()-J536)/30.44,0)) -> 51 | Q536: =IF(P536="","N/A",IF(P536<6,"🆕 < 6 mois",IF(P536<12,"📅 6-12 mois",IF(P536<24,"📆 1-2 ans","🗓️ > 2 ans")))) -> 🗓️ > 2 ans
A537: O_GMB_B17 | B537: DRC | C537: 704 | D537: 478 | E537: 0.67897727 | F537: 88 | G537: 37 | H537: 0.4205 | I537: =IF(H537="","N/A", IF(H537>=80%,"🔴 Saturé (≥80%)", IF(H537>=40%,"🟡 Attention (40-80%)", "🟢 Non saturé (<40%)" ) ) ) -> 🟡 Attention (40-80%) | J537: 44734 | K537: 0 | L537: M'bour | M537: Sindia | N537: Mbour | O537: Thiès | P537: =IF(J537="","",ROUND((TODAY()-J537)/30.44,0)) -> 51 | Q537: =IF(P537="","N/A",IF(P537<6,"🆕 < 6 mois",IF(P537<12,"📅 6-12 mois",IF(P537<24,"📆 1-2 ans","🗓️ > 2 ans")))) -> 🗓️ > 2 ans
A538: O_CAM_H17 | B538: DR2 | C538: 600 | D538: 500 | E538: 0.83333333 | F538: 75 | G538: 53 | H538: 0.7067 | I538: =IF(H538="","N/A", IF(H538>=80%,"🔴 Saturé (≥80%)", IF(H538>=40%,"🟡 Attention (40-80%)", "🟢 Non saturé (<40%)" ) ) ) -> 🟡 Attention (40-80%) | J538: 44739 | K538: Camberene | L538: Cambérène | M538: Parcelles Assainies | N538: Dakar | O538: Dakar | P538: =IF(J538="","",ROUND((TODAY()-J538)/30.44,0)) -> 50 | Q538: =IF(P538="","N/A",IF(P538<6,"🆕 < 6 mois",IF(P538<12,"📅 6-12 mois",IF(P538<24,"📆 1-2 ans","🗓️ > 2 ans")))) -> 🗓️ > 2 ans
A539: O_CAM_H51 | B539: DR2 | C539: 672 | D539: 529 | E539: 0.78720238 | F539: 84 | G539: 50 | H539: 0.5952 | I539: =IF(H539="","N/A", IF(H539>=80%,"🔴 Saturé (≥80%)", IF(H539>=40%,"🟡 Attention (40-80%)", "🟢 Non saturé (<40%)" ) ) ) -> 🟡 Attention (40-80%) | J539: 44739 | K539: Camberene | L539: Golf Sud | M539: Guediawaye | N539: Guédiawaye | O539: Dakar | P539: =IF(J539="","",ROUND((TODAY()-J539)/30.44,0)) -> 50 | Q539: =IF(P539="","N/A",IF(P539<6,"🆕 < 6 mois",IF(P539<12,"📅 6-12 mois",IF(P539<24,"📆 1-2 ans","🗓️ > 2 ans")))) -> 🗓️ > 2 ans
A540: O_GMB_B33 | B540: DRC | C540: 680 | D540: 342 | E540: 0.50294118 | F540: 85 | G540: 26 | H540: 0.3059 | I540: =IF(H540="","N/A", IF(H540>=80%,"🔴 Saturé (≥80%)", IF(H540>=40%,"🟡 Attention (40-80%)", "🟢 Non saturé (<40%)" ) ) ) -> 🟢 Non saturé (<40%) | J540: 44739 | K540: Saly Aérodrome | L540: Saly Portudal | M540: Sindia | N540: Mbour | O540: Thiès | P540: =IF(J540="","",ROUND((TODAY()-J540)/30.44,0)) -> 50 | Q540: =IF(P540="","N/A",IF(P540<6,"🆕 < 6 mois",IF(P540<12,"📅 6-12 mois",IF(P540<24,"📆 1-2 ans","🗓️ > 2 ans")))) -> 🗓️ > 2 ans
A541: O_GMB_B25 | B541: DRC | C541: 808 | D541: 517 | E541: 0.63985149 | F541: 101 | G541: 27 | H541: 0.2673 | I541: =IF(H541="","N/A", IF(H541>=80%,"🔴 Saturé (≥80%)", IF(H541>=40%,"🟡 Attention (40-80%)", "🟢 Non saturé (<40%)" ) ) ) -> 🟢 Non saturé (<40%) | J541: 44742 | K541: Grand Mbour | L541: M'bour | M541: Sindia | N541: Mbour | O541: Thiès | P541: =IF(J541="","",ROUND((TODAY()-J541)/30.44,0)) -> 50 | Q541: =IF(P541="","N/A",IF(P541<6,"🆕 < 6 mois",IF(P541<12,"📅 6-12 mois",IF(P541<24,"📆 1-2 ans","🗓️ > 2 ans")))) -> 🗓️ > 2 ans
A542: O_CAM_H57 | B542: DR2 | C542: 392 | D542: 335 | E542: 0.85459184 | F542: 49 | G542: 31 | H542: 0.6327 | I542: =IF(H542="","N/A", IF(H542>=80%,"🔴 Saturé (≥80%)", IF(H542>=40%,"🟡 Attention (40-80%)", "🟢 Non saturé (<40%)" ) ) ) -> 🟡 Attention (40-80%) | J542: 44746 | K542: Parcelle Unité 13 | L542: Parcelles Assainies | M542: Parcelles Assainies | N542: Dakar | O542: Dakar | P542: =IF(J542="","",ROUND((TODAY()-J542)/30.44,0)) -> 50 | Q542: =IF(P542="","N/A",IF(P542<6,"🆕 < 6 mois",IF(P542<12,"📅 6-12 mois",IF(P542<24,"📆 1-2 ans","🗓️ > 2 ans")))) -> 🗓️ > 2 ans
A543: O_CAM_H37 | B543: DR2 | C543: 704 | D543: 558 | E543: 0.79261364 | F543: 88 | G543: 55 | H543: 0.625 | I543: =IF(H543="","N/A", IF(H543>=80%,"🔴 Saturé (≥80%)", IF(H543>=40%,"🟡 Attention (40-80%)", "🟢 Non saturé (<40%)" ) ) ) -> 🟡 Attention (40-80%) | J543: 44746 | K543: Grand Médine | L543: Parcelles Assainies | M543: Parcelles Assainies | N543: Dakar | O543: Dakar | P543: =IF(J543="","",ROUND((TODAY()-J543)/30.44,0)) -> 50 | Q543: =IF(P543="","N/A",IF(P543<6,"🆕 < 6 mois",IF(P543<12,"📅 6-12 mois",IF(P543<24,"📆 1-2 ans","🗓️ > 2 ans")))) -> 🗓️ > 2 ans
A544: O_CAM_H58 | B544: DR2 | C544: 440 | D544: 344 | E544: 0.78181818 | F544: 55 | G544: 32 | H544: 0.5818 | I544: =IF(H544="","N/A", IF(H544>=80%,"🔴 Saturé (≥80%)", IF(H544>=40%,"🟡 Attention (40-80%)", "🟢 Non saturé (<40%)" ) ) ) -> 🟡 Attention (40-80%) | J544: 44746 | K544: Parcelle Unité 13 | L544: Parcelles Assainies | M544: Parcelles Assainies | N544: Dakar | O544: Dakar | P544: =IF(J544="","",ROUND((TODAY()-J544)/30.44,0)) -> 50 | Q544: =IF(P544="","N/A",IF(P544<6,"🆕 < 6 mois",IF(P544<12,"📅 6-12 mois",IF(P544<24,"📆 1-2 ans","🗓️ > 2 ans")))) -> 🗓️ > 2 ans
A545: O_MBW_R30 | B545: DR2 | C545: 688 | D545: 571 | E545: 0.82994186 | F545: 86 | G545: 66 | H545: 0.7674 | I545: =IF(H545="","N/A", IF(H545>=80%,"🔴 Saturé (≥80%)", IF(H545>=40%,"🟡 Attention (40-80%)", "🟢 Non saturé (<40%)" ) ) ) -> 🟡 Attention (40-80%) | J545: 44748 | K545: Zac Mbao | L545: Rufisque Ouest | M545: Rufisque | N545: Rufisque | O545: Dakar | P545: =IF(J545="","",ROUND((TODAY()-J545)/30.44,0)) -> 50 | Q545: =IF(P545="","N/A",IF(P545<6,"🆕 < 6 mois",IF(P545<12,"📅 6-12 mois",IF(P545<24,"📆 1-2 ans","🗓️ > 2 ans")))) -> 🗓️ > 2 ans
A546: O_MBW_R19 | B546: DR2 | C546: 512 | D546: 440 | E546: 0.859375 | F546: 64 | G546: 50 | H546: 0.7812 | I546: =IF(H546="","N/A", IF(H546>=80%,"🔴 Saturé (≥80%)", IF(H546>=40%,"🟡 Attention (40-80%)", "🟢 Non saturé (<40%)" ) ) ) -> 🟡 Attention (40-80%) | J546: 44748 | K546: Zac Mbao | L546: Rufisque Ouest | M546: Rufisque | N546: Rufisque | O546: Dakar | P546: =IF(J546="","",ROUND((TODAY()-J546)/30.44,0)) -> 50 | Q546: =IF(P546="","N/A",IF(P546<6,"🆕 < 6 mois",IF(P546<12,"📅 6-12 mois",IF(P546<24,"📆 1-2 ans","🗓️ > 2 ans")))) -> 🗓️ > 2 ans
...

Sheet Taux de pénétration par plaque
A1: PLAQUE | B1: Zone DR | C1: EQL PLAQUES | D1: TAUX D'OCCUPATION | E1: Taux de PBO saturé | F1: Statut occupation | G1: Date ouverture | H1: Date Aujourdhui | I1: Age de la plaque en Mois | J1: ZONES | K1: Commune | L1: Arrondissement | M1: Département | N1: Région
A2: O_MED_A03 | B2: DR1 | C2: 1736 | D2: 0.35368664 | E2: 0.3506 | F2: =IF(D2>=0.9,"🔴 Saturé",IF(D2>=0.6,"🟠 Occupation moyenne","🟢 Disponible")) -> 🟢 Disponible | G2: 43045 | H2: =TODAY() -> 46273 | I2: =DATEDIF(G2,H2,"m") -> 106 | J2: Plateau | K2: Dakar-Plateau | L2: Dakar-Plateau | M2: Dakar | N2: Dakar
A3: O_SVD_C10 | B3: DR1 | C3: 3830 | D3: 0.46057441 | E3: 0.2985 | F3: =IF(D3>=0.9,"🔴 Saturé",IF(D3>=0.6,"🟠 Occupation moyenne","🟢 Disponible")) -> 🟢 Disponible | G3: 43045 | H3: =TODAY() -> 46273 | I3: =DATEDIF(G3,H3,"m") -> 106 | J3: Keur Gorgui, Sacré Cœur pyrotechnie | K3: Mermoz-Sacré-Cœur | L3: Almadies | M3: Dakar | N3: Dakar
A4: O_REP_A04 | B4: DR1 | C4: 268 | D4: 0.35447761 | E4: 0.0769 | F4: =IF(D4>=0.9,"🔴 Saturé",IF(D4>=0.6,"🟠 Occupation moyenne","🟢 Disponible")) -> 🟢 Disponible | G4: 43045 | H4: =TODAY() -> 46273 | I4: =DATEDIF(G4,H4,"m") -> 106 | J4: Plateau | K4: Dakar-Plateau | L4: Dakar-Plateau | M4: Dakar | N4: Dakar
A5: O_REP_B15 | B5: DR1 | C5: 808 | D5: 0.39975248 | E5: 0.1471 | F5: =IF(D5>=0.9,"🔴 Saturé",IF(D5>=0.6,"🟠 Occupation moyenne","🟢 Disponible")) -> 🟢 Disponible | G5: 43046 | H5: =TODAY() -> 46273 | I5: =DATEDIF(G5,H5,"m") -> 106 | J5: Plateau | K5: Dakar-Plateau | L5: Dakar-Plateau | M5: Dakar | N5: Dakar
A6: O_REP_A11 | B6: DR1 | C6: 666 | D6: 0.36486486 | E6: 0.1087 | F6: =IF(D6>=0.9,"🔴 Saturé",IF(D6>=0.6,"🟠 Occupation moyenne","🟢 Disponible")) -> 🟢 Disponible | G6: 43046 | H6: =TODAY() -> 46273 | I6: =DATEDIF(G6,H6,"m") -> 106 | J6: Plateau | K6: Dakar-Plateau | L6: Dakar-Plateau | M6: Dakar | N6: Dakar
A7: O_REP_A12 | B7: DR1 | C7: 476 | D7: 0.34033613 | E7: 0.0667 | F7: =IF(D7>=0.9,"🔴 Saturé",IF(D7>=0.6,"🟠 Occupation moyenne","🟢 Disponible")) -> 🟢 Disponible | G7: 43046 | H7: =TODAY() -> 46273 | I7: =DATEDIF(G7,H7,"m") -> 106 | J7: Plateau | K7: Dakar-Plateau | L7: Dakar-Plateau | M7: Dakar | N7: Dakar
A8: O_REP_B17 | B8: DR1 | C8: 760 | D8: 0.45921053 | E8: 0.2812 | F8: =IF(D8>=0.9,"🔴 Saturé",IF(D8>=0.6,"🟠 Occupation moyenne","🟢 Disponible")) -> 🟢 Disponible | G8: 43053 | H8: =TODAY() -> 46273 | I8: =DATEDIF(G8,H8,"m") -> 105 | J8: Plateau | K8: Dakar-Plateau | L8: Dakar-Plateau | M8: Dakar | N8: Dakar
A9: O_REP_A09 | B9: DR1 | C9: 1340 | D9: 0.44552239 | E9: 0.1791 | F9: =IF(D9>=0.9,"🔴 Saturé",IF(D9>=0.6,"🟠 Occupation moyenne","🟢 Disponible")) -> 🟢 Disponible | G9: 43053 | H9: =TODAY() -> 46273 | I9: =DATEDIF(G9,H9,"m") -> 105 | J9: Plateau | K9: Dakar-Plateau | L9: Dakar-Plateau | M9: Dakar | N9: Dakar
A10: O_REP_A05 | B10: DR1 | C10: 850 | D10: 0.40588235 | E10: 0.2353 | F10: =IF(D10>=0.9,"🔴 Saturé",IF(D10>=0.6,"🟠 Occupation moyenne","🟢 Disponible")) -> 🟢 Disponible | G10: 43059 | H10: =TODAY() -> 46273 | I10: =DATEDIF(G10,H10,"m") -> 105 | J10: Plateau | K10: Dakar-Plateau | L10: Dakar-Plateau | M10: Dakar | N10: Dakar
A11: O_REP_A02 | B11: DR1 | C11: 1124 | D11: 0.50177936 | E11: 0.2203 | F11: =IF(D11>=0.9,"🔴 Saturé",IF(D11>=0.6,"🟠 Occupation moyenne","🟢 Disponible")) -> 🟢 Disponible | G11: 43074 | H11: =TODAY() -> 46273 | I11: =DATEDIF(G11,H11,"m") -> 105 | J11: Plateau | K11: Dakar-Plateau | L11: Dakar-Plateau | M11: Dakar | N11: Dakar
A12: O_REP_A08 | B12: DR1 | C12: 1348 | D12: 0.36127596 | E12: 0.1724 | F12: =IF(D12>=0.9,"🔴 Saturé",IF(D12>=0.6,"🟠 Occupation moyenne","🟢 Disponible")) -> 🟢 Disponible | G12: 43095 | H12: =TODAY() -> 46273 | I12: =DATEDIF(G12,H12,"m") -> 104 | J12: Plateau | K12: Dakar-Plateau | L12: Dakar-Plateau | M12: Dakar | N12: Dakar
A13: O_REP_A10 | B13: DR1 | C13: 320 | D13: 0.221875 | E13: 0.1034 | F13: =IF(D13>=0.9,"🔴 Saturé",IF(D13>=0.6,"🟠 Occupation moyenne","🟢 Disponible")) -> 🟢 Disponible | G13: 43096 | H13: =TODAY() -> 46273 | I13: =DATEDIF(G13,H13,"m") -> 104 | J13: Plateau | K13: Dakar-Plateau | L13: Dakar-Plateau | M13: Dakar | N13: Dakar
... A483: O_KMR_L40 | B483: DR2 | C483: 1068 | D483: 0.64044944 | E483: 0.4607 | F483: =IF(D483>=0.9,"🔴 Saturé",IF(D483>=0.6,"🟠 Occupation moyenne","🟢 Disponible")) -> 🟠 Occupation moyenne | G483: 44582 | H483: =TODAY() -> 46273 | I483: =DATEDIF(G483,H483,"m") -> 55 | J483: Keur Massar | K483: Keur Massar Nord | L483: Malika | M483: Keur Massar | N483: Dakar
A484: O_GDW_M15 | B484: DR2 | C484: 792 | D484: 0.64393939 | E484: 0.4733 | F484: =IF(D484>=0.9,"🔴 Saturé",IF(D484>=0.6,"🟠 Occupation moyenne","🟢 Disponible")) -> 🟠 Occupation moyenne | G484: 44591 | H484: =TODAY() -> 46273 | I484: =DATEDIF(G484,H484,"m") -> 55 | J484: 0 | K484: Golf Sud | L484: Guediawaye | M484: Guédiawaye | N484: Dakar
A485: O_THS_A10 | B485: DRC | C485: 1430 | D485: 0.58251748 | E485: 0.4538 | F485: =IF(D485>=0.9,"🔴 Saturé",IF(D485>=0.6,"🟠 Occupation moyenne","🟢 Disponible")) -> 🟢 Disponible | G485: 44591 | H485: =TODAY() -> 46273 | I485: =DATEDIF(G485,H485,"m") -> 55 | J485: Thies Nguinth | K485: Thiès Nord | L485: Thies Nord | M485: Thiès | N485: Thiès
A486: O_TIV_A07 | B486: DRC | C486: 452 | D486: 0.59955752 | E486: 0.5333 | F486: =IF(D486>=0.9,"🔴 Saturé",IF(D486>=0.6,"🟠 Occupation moyenne","🟢 Disponible")) -> 🟢 Disponible | G486: 44591 | H486: =TODAY() -> 46273 | I486: =DATEDIF(G486,H486,"m") -> 55 | J486: Quartier derriere EDK | K486: Tivaouane | L486: Pambal | M486: Tivaouane | N486: Thiès
A487: O_THS_A09 | B487: DRC | C487: 590 | D487: 0.75084746 | E487: 0.6837 | F487: =IF(D487>=0.9,"🔴 Saturé",IF(D487>=0.6,"🟠 Occupation moyenne","🟢 Disponible")) -> 🟠 Occupation moyenne | G487: 44591 | H487: =TODAY() -> 46273 | I487: =DATEDIF(G487,H487,"m") -> 55 | J487: Fahu | K487: Fandène | L487: Keur Moussa | M487: Thiès | N487: Thiès
A488: O_KLK_A19 | B488: DRE | C488: 984 | D488: 0.55386179 | E488: 0.311 | F488: =IF(D488>=0.9,"🔴 Saturé",IF(D488>=0.6,"🟠 Occupation moyenne","🟢 Disponible")) -> 🟢 Disponible | G488: 44591 | H488: =TODAY() -> 46273 | I488: =DATEDIF(G488,H488,"m") -> 55 | J488: Kahone | K488: Kahone | L488: Kahone | M488: Kaolack | N488: Kaolack
A489: O_THS_A31 | B489: DRC | C489: 852 | D489: 0.65258216 | E489: 0.4366 | F489: =IF(D489>=0.9,"🔴 Saturé",IF(D489>=0.6,"🟠 Occupation moyenne","🟢 Disponible")) -> 🟠 Occupation moyenne | G489: 44591 | H489: =TODAY() -> 46273 | I489: =DATEDIF(G489,H489,"m") -> 55 | J489: Thies Nguinth | K489: Thiès Nord | L489: Thies Nord | M489: Thiès | N489: Thiès
A490: O_DKH_A00 | B490: DRT | C490: 528 | D490: 0.75757576 | E490: 0.6212 | F490: =IF(D490>=0.9,"🔴 Saturé",IF(D490>=0.6,"🟠 Occupation moyenne","🟢 Disponible")) -> 🟠 Occupation moyenne | G490: 44622 | H490: =TODAY() -> 46273 | I490: =DATEDIF(G490,H490,"m") -> 54 | J490: Darou Khoudoss 1, Touba Alie 1 | K490: Touba Mosquée | L490: Ndame | M490: Mbacké | N490: Diourbel
A491: O_DKH_A15 | B491: DRT | C491: 512 | D491: 0.66210938 | E491: 0.3438 | F491: =IF(D491>=0.9,"🔴 Saturé",IF(D491>=0.6,"🟠 Occupation moyenne","🟢 Disponible")) -> 🟠 Occupation moyenne | G491: 44622 | H491: =TODAY() -> 46273 | I491: =DATEDIF(G491,H491,"m") -> 54 | J491: Darou Khoudoss 5 | K491: Touba Mosquée | L491: Ndame | M491: Mbacké | N491: Diourbel
A492: O_TIA_E27 | B492: DR2 | C492: 488 | D492: 0.77663934 | E492: 0.6885 | F492: =IF(D492>=0.9,"🔴 Saturé",IF(D492>=0.6,"🟠 Occupation moyenne","🟢 Disponible")) -> 🟠 Occupation moyenne | G492: 44662 | H492: =TODAY() -> 46273 | I492: =DATEDIF(G492,H492,"m") -> 52 | J492: Thiaroye,Sam-Sam4 | K492: Diamaguène-Sicap Mbao | L492: Ville de Pikine | M492: Pikine | N492: Dakar
A493: O_KMR_L45 | B493: DR2 | C493: 752 | D493: 0.75 | E493: 0.6596 | F493: =IF(D493>=0.9,"🔴 Saturé",IF(D493>=0.6,"🟠 Occupation moyenne","🟢 Disponible")) -> 🟠 Occupation moyenne | G493: 44671 | H493: =TODAY() -> 46273 | I493: =DATEDIF(G493,H493,"m") -> 52 | J493: Keur Massar, Unité 4 | K493: Keur Massar Nord | L493: Malika | M493: Keur Massar | N493: Dakar
A494: O_MBR_A06 | B494: DRC | C494: 720 | D494: 0.71111111 | E494: 0.5333 | F494: =IF(D494>=0.9,"🔴 Saturé",IF(D494>=0.6,"🟠 Occupation moyenne","🟢 Disponible")) -> 🟠 Occupation moyenne | G494: 44671 | H494: =TODAY() -> 46273 | I494: =DATEDIF(G494,H494,"m") -> 52 | J494: Mbour FH, Warang_Soce | K494: Malicounda | L494: Sindia | M494: Mbour | N494: Thiès
A495: O_DKH_A17 | B495: DRT | C495: 456 | D495: 0.6995614 | E495: 0.4561 | F495: =IF(D495>=0.9,"🔴 Saturé",IF(D495>=0.6,"🟠 Occupation moyenne","🟢 Disponible")) -> 🟠 Occupation moyenne | G495: 44672 | H495: =TODAY() -> 46273 | I495: =DATEDIF(G495,H495,"m") -> 52 | J495: Touba Guédé | K495: Touba Mosquée | L495: Ndame | M495: Mbacké | N495: Diourbel
A496: O_DKH_A16 | B496: DRT | C496: 440 | D496: 0.71363636 | E496: 0.3636 | F496: =IF(D496>=0.9,"🔴 Saturé",IF(D496>=0.6,"🟠 Occupation moyenne","🟢 Disponible")) -> 🟠 Occupation moyenne | G496: 44672 | H496: =TODAY() -> 46273 | I496: =DATEDIF(G496,H496,"m") -> 52 | J496: Darou Khoudoss 1, Touba Alie 1 | K496: Touba Mosquée | L496: Ndame | M496: Mbacké | N496: Diourbel
... A534: O_KMR_L05 | B534: DR2 | C534: 624 | D534: 0.82051282 | E534: 0.641 | F534: =IF(D534>=0.9,"🔴 Saturé",IF(D534>=0.6,"🟠 Occupation moyenne","🟢 Disponible")) -> 🟠 Occupation moyenne | G534: 44728 | H534: =TODAY() -> 46273 | I534: =DATEDIF(G534,H534,"m") -> 50 | J534: Malika | K534: Yeumbeul Nord | L534: Yeumbeul | M534: Keur Massar | N534: Dakar
A535: O_GDW_M16 | B535: DR2 | C535: 600 | D535: 0.70166667 | E535: 0.5067 | F535: =IF(D535>=0.9,"🔴 Saturé",IF(D535>=0.6,"🟠 Occupation moyenne","🟢 Disponible")) -> 🟠 Occupation moyenne | G535: 44734 | H535: =TODAY() -> 46273 | I535: =DATEDIF(G535,H535,"m") -> 50 | J535: 0 | K535: Golf Sud | L535: Guediawaye | M535: Guédiawaye | N535: Dakar
A536: O_GMB_B27 | B536: DRC | C536: 776 | D536: 0.55412371 | E536: 0.2784 | F536: =IF(D536>=0.9,"🔴 Saturé",IF(D536>=0.6,"🟠 Occupation moyenne","🟢 Disponible")) -> 🟢 Disponible | G536: 44734 | H536: =TODAY() -> 46273 | I536: =DATEDIF(G536,H536,"m") -> 50 | J536: 0 | K536: Saly Portudal | L536: Sindia | M536: Mbour | N536: Thiès
A537: O_GMB_B17 | B537: DRC | C537: 704 | D537: 0.67897727 | E537: 0.4205 | F537: =IF(D537>=0.9,"🔴 Saturé",IF(D537>=0.6,"🟠 Occupation moyenne","🟢 Disponible")) -> 🟠 Occupation moyenne | G537: 44734 | H537: =TODAY() -> 46273 | I537: =DATEDIF(G537,H537,"m") -> 50 | J537: 0 | K537: M'bour | L537: Sindia | M537: Mbour | N537: Thiès
A538: O_CAM_H17 | B538: DR2 | C538: 600 | D538: 0.83333333 | E538: 0.7067 | F538: =IF(D538>=0.9,"🔴 Saturé",IF(D538>=0.6,"🟠 Occupation moyenne","🟢 Disponible")) -> 🟠 Occupation moyenne | G538: 44739 | H538: =TODAY() -> 46273 | I538: =DATEDIF(G538,H538,"m") -> 50 | J538: Camberene | K538: Cambérène | L538: Parcelles Assainies | M538: Dakar | N538: Dakar
A539: O_CAM_H51 | B539: DR2 | C539: 672 | D539: 0.78720238 | E539: 0.5952 | F539: =IF(D539>=0.9,"🔴 Saturé",IF(D539>=0.6,"🟠 Occupation moyenne","🟢 Disponible")) -> 🟠 Occupation moyenne | G539: 44739 | H539: =TODAY() -> 46273 | I539: =DATEDIF(G539,H539,"m") -> 50 | J539: Camberene | K539: Golf Sud | L539: Guediawaye | M539: Guédiawaye | N539: Dakar
A540: O_GMB_B33 | B540: DRC | C540: 680 | D540: 0.50294118 | E540: 0.3059 | F540: =IF(D540>=0.9,"🔴 Saturé",IF(D540>=0.6,"🟠 Occupation moyenne","🟢 Disponible")) -> 🟢 Disponible | G540: 44739 | H540: =TODAY() -> 46273 | I540: =DATEDIF(G540,H540,"m") -> 50 | J540: Saly Aérodrome | K540: Saly Portudal | L540: Sindia | M540: Mbour | N540: Thiès
A541: O_GMB_B25 | B541: DRC | C541: 808 | D541: 0.63985149 | E541: 0.2673 | F541: =IF(D541>=0.9,"🔴 Saturé",IF(D541>=0.6,"🟠 Occupation moyenne","🟢 Disponible")) -> 🟠 Occupation moyenne | G541: 44742 | H541: =TODAY() -> 46273 | I541: =DATEDIF(G541,H541,"m") -> 50 | J541: Grand Mbour | K541: M'bour | L541: Sindia | M541: Mbour | N541: Thiès
A542: O_CAM_H57 | B542: DR2 | C542: 392 | D542: 0.85459184 | E542: 0.6327 | F542: =IF(D542>=0.9,"🔴 Saturé",IF(D542>=0.6,"🟠 Occupation moyenne","🟢 Disponible")) -> 🟠 Occupation moyenne | G542: 44746 | H542: =TODAY() -> 46273 | I542: =DATEDIF(G542,H542,"m") -> 50 | J542: Parcelle Unité 13 | K542: Parcelles Assainies | L542: Parcelles Assainies | M542: Dakar | N542: Dakar
A543: O_CAM_H37 | B543: DR2 | C543: 704 | D543: 0.79261364 | E543: 0.625 | F543: =IF(D543>=0.9,"🔴 Saturé",IF(D543>=0.6,"🟠 Occupation moyenne","🟢 Disponible")) -> 🟠 Occupation moyenne | G543: 44746 | H543: =TODAY() -> 46273 | I543: =DATEDIF(G543,H543,"m") -> 50 | J543: Grand Médine | K543: Parcelles Assainies | L543: Parcelles Assainies | M543: Dakar | N543: Dakar
A544: O_CAM_H58 | B544: DR2 | C544: 440 | D544: 0.78181818 | E544: 0.5818 | F544: =IF(D544>=0.9,"🔴 Saturé",IF(D544>=0.6,"🟠 Occupation moyenne","🟢 Disponible")) -> 🟠 Occupation moyenne | G544: 44746 | H544: =TODAY() -> 46273 | I544: =DATEDIF(G544,H544,"m") -> 50 | J544: Parcelle Unité 13 | K544: Parcelles Assainies | L544: Parcelles Assainies | M544: Dakar | N544: Dakar
A545: O_MBW_R30 | B545: DR2 | C545: 688 | D545: 0.82994186 | E545: 0.7674 | F545: =IF(D545>=0.9,"🔴 Saturé",IF(D545>=0.6,"🟠 Occupation moyenne","🟢 Disponible")) -> 🟠 Occupation moyenne | G545: 44748 | H545: =TODAY() -> 46273 | I545: =DATEDIF(G545,H545,"m") -> 50 | J545: Zac Mbao | K545: Rufisque Ouest | L545: Rufisque | M545: Rufisque | N545: Dakar
A546: O_MBW_R19 | B546: DR2 | C546: 512 | D546: 0.859375 | E546: 0.7812 | F546: =IF(D546>=0.9,"🔴 Saturé",IF(D546>=0.6,"🟠 Occupation moyenne","🟢 Disponible")) -> 🟠 Occupation moyenne | G546: 44748 | H546: =TODAY() -> 46273 | I546: =DATEDIF(G546,H546,"m") -> 50 | J546: Zac Mbao | K546: Rufisque Ouest | L546: Rufisque | M546: Rufisque | N546: Dakar
...

Sheet Evolution des plaques
A1: Plaques | B1: ARCHI | C1: Zone DR | D1: Date d'ouverture | E1: Date Aujourdhui | F1: Zone de couverture | G1: Taux de pénétration S35_26 | H1: Taux de pénétration S36_26 | I1: Taux d'évolution | J1: Age | K1: Tendance évolution
A2: O_MED_A03 | B2: ZONE TRES DENSE | C2: DR1 | D2: 43045 | E2: =TODAY() -> 46273 | F2: Plateau | G2: 0.35253456 | H2: =VLOOKUP(A2,[3]Sheet1!$A:$H,8,) -> 0.35368664 | I2: =H2-G2 -> 0.0011520737 | J2: =DATEDIF(D2,E2,"m") -> 106 | K2: =IF(H2="","➡️ Stable",IF(H2>0.005,"⬆️ En hausse",IF(H2<-0.005,"⬇️ En baisse","➡️ Stable"))) -> ⬆️ En hausse
A3: O_REP_A04 | B3: ZONE TRES DENSE | C3: DR1 | D3: 43045 | E3: =TODAY() -> 46273 | F3: Plateau | G3: 0.35074627 | H3: =VLOOKUP(A3,[3]Sheet1!$A:$H,8,) -> 0.35447761 | I3: =H3-G3 -> 0.0037313433 | J3: =DATEDIF(D3,E3,"m") -> 106 | K3: =IF(H3="","➡️ Stable",IF(H3>0.005,"⬆️ En hausse",IF(H3<-0.005,"⬇️ En baisse","➡️ Stable"))) -> ⬆️ En hausse
A4: O_SVD_C10 | B4: ZONE TRES DENSE | C4: DR1 | D4: 43045 | E4: =TODAY() -> 46273 | F4: Keur Gorgui, Sacré Cœur pyrotechnie | G4: 0.46083551 | H4: =VLOOKUP(A4,[3]Sheet1!$A:$H,8,) -> 0.46057441 | I4: =H4-G4 -> -0.00026109661 | J4: =DATEDIF(D4,E4,"m") -> 106 | K4: =IF(H4="","➡️ Stable",IF(H4>0.005,"⬆️ En hausse",IF(H4<-0.005,"⬇️ En baisse","➡️ Stable"))) -> ⬆️ En hausse
A5: O_REP_A11 | B5: ZONE TRES DENSE | C5: DR1 | D5: 43046 | E5: =TODAY() -> 46273 | F5: Plateau | G5: 0.36786787 | H5: =VLOOKUP(A5,[3]Sheet1!$A:$H,8,) -> 0.36486486 | I5: =H5-G5 -> -0.003003003 | J5: =DATEDIF(D5,E5,"m") -> 106 | K5: =IF(H5="","➡️ Stable",IF(H5>0.005,"⬆️ En hausse",IF(H5<-0.005,"⬇️ En baisse","➡️ Stable"))) -> ⬆️ En hausse
A6: O_REP_A12 | B6: ZONE TRES DENSE | C6: DR1 | D6: 43046 | E6: =TODAY() -> 46273 | F6: Plateau | G6: 0.34033613 | H6: =VLOOKUP(A6,[3]Sheet1!$A:$H,8,) -> 0.34033613 | I6: =H6-G6 -> 0 | J6: =DATEDIF(D6,E6,"m") -> 106 | K6: =IF(H6="","➡️ Stable",IF(H6>0.005,"⬆️ En hausse",IF(H6<-0.005,"⬇️ En baisse","➡️ Stable"))) -> ⬆️ En hausse
A7: O_REP_B15 | B7: ZONE TRES DENSE | C7: DR1 | D7: 43046 | E7: =TODAY() -> 46273 | F7: Plateau | G7: 0.39851485 | H7: =VLOOKUP(A7,[3]Sheet1!$A:$H,8,) -> 0.39975248 | I7: =H7-G7 -> 0.0012376238 | J7: =DATEDIF(D7,E7,"m") -> 106 | K7: =IF(H7="","➡️ Stable",IF(H7>0.005,"⬆️ En hausse",IF(H7<-0.005,"⬇️ En baisse","➡️ Stable"))) -> ⬆️ En hausse
A8: O_REP_A09 | B8: ZONE TRES DENSE | C8: DR1 | D8: 43053 | E8: =TODAY() -> 46273 | F8: Plateau | G8: 0.44626866 | H8: =VLOOKUP(A8,[3]Sheet1!$A:$H,8,) -> 0.44552239 | I8: =H8-G8 -> -0.00074626866 | J8: =DATEDIF(D8,E8,"m") -> 105 | K8: =IF(H8="","➡️ Stable",IF(H8>0.005,"⬆️ En hausse",IF(H8<-0.005,"⬇️ En baisse","➡️ Stable"))) -> ⬆️ En hausse
A9: O_REP_B17 | B9: ZONE TRES DENSE | C9: DR1 | D9: 43053 | E9: =TODAY() -> 46273 | F9: Plateau | G9: 0.45131579 | H9: =VLOOKUP(A9,[3]Sheet1!$A:$H,8,) -> 0.45921053 | I9: =H9-G9 -> 0.0078947368 | J9: =DATEDIF(D9,E9,"m") -> 105 | K9: =IF(H9="","➡️ Stable",IF(H9>0.005,"⬆️ En hausse",IF(H9<-0.005,"⬇️ En baisse","➡️ Stable"))) -> ⬆️ En hausse
A10: O_REP_A05 | B10: ZONE TRES DENSE | C10: DR1 | D10: 43059 | E10: =TODAY() -> 46273 | F10: Plateau | G10: 0.40823529 | H10: =VLOOKUP(A10,[3]Sheet1!$A:$H,8,) -> 0.40588235 | I10: =H10-G10 -> -0.0023529412 | J10: =DATEDIF(D10,E10,"m") -> 105 | K10: =IF(H10="","➡️ Stable",IF(H10>0.005,"⬆️ En hausse",IF(H10<-0.005,"⬇️ En baisse","➡️ Stable"))) -> ⬆️ En hausse
A11: O_REP_A02 | B11: ZONE TRES DENSE | C11: DR1 | D11: 43074 | E11: =TODAY() -> 46273 | F11: Plateau | G11: 0.50266904 | H11: =VLOOKUP(A11,[3]Sheet1!$A:$H,8,) -> 0.50177936 | I11: =H11-G11 -> -0.00088967972 | J11: =DATEDIF(D11,E11,"m") -> 105 | K11: =IF(H11="","➡️ Stable",IF(H11>0.005,"⬆️ En hausse",IF(H11<-0.005,"⬇️ En baisse","➡️ Stable"))) -> ⬆️ En hausse
A12: O_REP_A08 | B12: ZONE TRES DENSE | C12: DR1 | D12: 43095 | E12: =TODAY() -> 46273 | F12: Plateau | G12: 0.3620178 | H12: =VLOOKUP(A12,[3]Sheet1!$A:$H,8,) -> 0.36127596 | I12: =H12-G12 -> -0.00074183976 | J12: =DATEDIF(D12,E12,"m") -> 104 | K12: =IF(H12="","➡️ Stable",IF(H12>0.005,"⬆️ En hausse",IF(H12<-0.005,"⬇️ En baisse","➡️ Stable"))) -> ⬆️ En hausse
A13: O_REP_A10 | B13: ZONE TRES DENSE | C13: DR1 | D13: 43096 | E13: =TODAY() -> 46273 | F13: Plateau | G13: 0.221875 | H13: =VLOOKUP(A13,[3]Sheet1!$A:$H,8,) -> 0.221875 | I13: =H13-G13 -> 0 | J13: =DATEDIF(D13,E13,"m") -> 104 | K13: =IF(H13="","➡️ Stable",IF(H13>0.005,"⬆️ En hausse",IF(H13<-0.005,"⬇️ En baisse","➡️ Stable"))) -> ⬆️ En hausse
... A483: O_KMR_L40 | B483: ZONE TRES DENSE | C483: DR2 | D483: 44582 | E483: =TODAY() -> 46273 | F483: Keur Massar | G483: 0.63764045 | H483: =VLOOKUP(A483,[3]Sheet1!$A:$H,8,) -> 0.64044944 | I483: =H483-G483 -> 0.0028089888 | J483: =DATEDIF(D483,E483,"m") -> 55 | K483: =IF(H483="","➡️ Stable",IF(H483>0.005,"⬆️ En hausse",IF(H483<-0.005,"⬇️ En baisse","➡️ Stable"))) -> ⬆️ En hausse
A484: O_GDW_M15 | B484: ZONE TRES DENSE | C484: DR2 | D484: 44591 | E484: =TODAY() -> 46273 | G484: 0.63636364 | H484: =VLOOKUP(A484,[3]Sheet1!$A:$H,8,) -> 0.64393939 | I484: =H484-G484 -> 0.0075757576 | J484: =DATEDIF(D484,E484,"m") -> 55 | K484: =IF(H484="","➡️ Stable",IF(H484>0.005,"⬆️ En hausse",IF(H484<-0.005,"⬇️ En baisse","➡️ Stable"))) -> ⬆️ En hausse
A485: O_KLK_A19 | B485: PMZ | C485: DRE | D485: 44591 | E485: =TODAY() -> 46273 | F485: Kahone | G485: 0.55081301 | H485: =VLOOKUP(A485,[3]Sheet1!$A:$H,8,) -> 0.55386179 | I485: =H485-G485 -> 0.0030487805 | J485: =DATEDIF(D485,E485,"m") -> 55 | K485: =IF(H485="","➡️ Stable",IF(H485>0.005,"⬆️ En hausse",IF(H485<-0.005,"⬇️ En baisse","➡️ Stable"))) -> ⬆️ En hausse
A486: O_THS_A09 | B486: ZONE TRES DENSE | C486: DRC | D486: 44591 | E486: =TODAY() -> 46273 | F486: Fahu | G486: 0.75423729 | H486: =VLOOKUP(A486,[3]Sheet1!$A:$H,8,) -> 0.75084746 | I486: =H486-G486 -> -0.0033898305 | J486: =DATEDIF(D486,E486,"m") -> 55 | K486: =IF(H486="","➡️ Stable",IF(H486>0.005,"⬆️ En hausse",IF(H486<-0.005,"⬇️ En baisse","➡️ Stable"))) -> ⬆️ En hausse
A487: O_THS_A10 | B487: ZONE TRES DENSE | C487: DRC | D487: 44591 | E487: =TODAY() -> 46273 | F487: Thies Nguinth | G487: 0.58111888 | H487: =VLOOKUP(A487,[3]Sheet1!$A:$H,8,) -> 0.58251748 | I487: =H487-G487 -> 0.0013986014 | J487: =DATEDIF(D487,E487,"m") -> 55 | K487: =IF(H487="","➡️ Stable",IF(H487>0.005,"⬆️ En hausse",IF(H487<-0.005,"⬇️ En baisse","➡️ Stable"))) -> ⬆️ En hausse
A488: O_THS_A31 | B488: PMZ | C488: DRC | D488: 44591 | E488: =TODAY() -> 46273 | F488: Thies Nguinth | G488: 0.65140845 | H488: =VLOOKUP(A488,[3]Sheet1!$A:$H,8,) -> 0.65258216 | I488: =H488-G488 -> 0.0011737089 | J488: =DATEDIF(D488,E488,"m") -> 55 | K488: =IF(H488="","➡️ Stable",IF(H488>0.005,"⬆️ En hausse",IF(H488<-0.005,"⬇️ En baisse","➡️ Stable"))) -> ⬆️ En hausse
A489: O_TIV_A07 | B489: OODN | C489: DRC | D489: 44591 | E489: =TODAY() -> 46273 | F489: Quartier derriere EDK | G489: 0.59292035 | H489: =VLOOKUP(A489,[3]Sheet1!$A:$H,8,) -> 0.59955752 | I489: =H489-G489 -> 0.0066371681 | J489: =DATEDIF(D489,E489,"m") -> 55 | K489: =IF(H489="","➡️ Stable",IF(H489>0.005,"⬆️ En hausse",IF(H489<-0.005,"⬇️ En baisse","➡️ Stable"))) -> ⬆️ En hausse
A490: O_DKH_A00 | B490: OODN | C490: DRT | D490: 44622 | E490: =TODAY() -> 46273 | F490: Darou Khoudoss 1, Touba Alie 1 | G490: 0.75757576 | H490: =VLOOKUP(A490,[3]Sheet1!$A:$H,8,) -> 0.75757576 | I490: =H490-G490 -> 0 | J490: =DATEDIF(D490,E490,"m") -> 54 | K490: =IF(H490="","➡️ Stable",IF(H490>0.005,"⬆️ En hausse",IF(H490<-0.005,"⬇️ En baisse","➡️ Stable"))) -> ⬆️ En hausse
A491: O_DKH_A15 | B491: OODN | C491: DRT | D491: 44622 | E491: =TODAY() -> 46273 | F491: Darou Khoudoss 5 | G491: 0.66015625 | H491: =VLOOKUP(A491,[3]Sheet1!$A:$H,8,) -> 0.66210938 | I491: =H491-G491 -> 0.001953125 | J491: =DATEDIF(D491,E491,"m") -> 54 | K491: =IF(H491="","➡️ Stable",IF(H491>0.005,"⬆️ En hausse",IF(H491<-0.005,"⬇️ En baisse","➡️ Stable"))) -> ⬆️ En hausse
A492: O_TIA_E27 | B492: OODN | C492: DR2 | D492: 44662 | E492: =TODAY() -> 46273 | F492: Thiaroye,Sam-Sam4 | G492: 0.77663934 | H492: =VLOOKUP(A492,[3]Sheet1!$A:$H,8,) -> 0.77663934 | I492: =H492-G492 -> 0 | J492: =DATEDIF(D492,E492,"m") -> 52 | K492: =IF(H492="","➡️ Stable",IF(H492>0.005,"⬆️ En hausse",IF(H492<-0.005,"⬇️ En baisse","➡️ Stable"))) -> ⬆️ En hausse
A493: O_KMR_L45 | B493: OODN | C493: DR2 | D493: 44671 | E493: =TODAY() -> 46273 | F493: Keur Massar, Unité 4 | G493: 0.75 | H493: =VLOOKUP(A493,[3]Sheet1!$A:$H,8,) -> 0.75 | I493: =H493-G493 -> 0 | J493: =DATEDIF(D493,E493,"m") -> 52 | K493: =IF(H493="","➡️ Stable",IF(H493>0.005,"⬆️ En hausse",IF(H493<-0.005,"⬇️ En baisse","➡️ Stable"))) -> ⬆️ En hausse
A494: O_MBR_A06 | B494: OODN | C494: DRC | D494: 44671 | E494: =TODAY() -> 46273 | F494: Mbour FH, Warang_Soce | G494: 0.70972222 | H494: =VLOOKUP(A494,[3]Sheet1!$A:$H,8,) -> 0.71111111 | I494: =H494-G494 -> 0.0013888889 | J494: =DATEDIF(D494,E494,"m") -> 52 | K494: =IF(H494="","➡️ Stable",IF(H494>0.005,"⬆️ En hausse",IF(H494<-0.005,"⬇️ En baisse","➡️ Stable"))) -> ⬆️ En hausse
A495: O_DKH_A16 | B495: OODN | C495: DRT | D495: 44672 | E495: =TODAY() -> 46273 | F495: Darou Khoudoss 1, Touba Alie 1 | G495: 0.71363636 | H495: =VLOOKUP(A495,[3]Sheet1!$A:$H,8,) -> 0.71363636 | I495: =H495-G495 -> 0 | J495: =DATEDIF(D495,E495,"m") -> 52 | K495: =IF(H495="","➡️ Stable",IF(H495>0.005,"⬆️ En hausse",IF(H495<-0.005,"⬇️ En baisse","➡️ Stable"))) -> ⬆️ En hausse
A496: O_DKH_A17 | B496: OODN | C496: DRT | D496: 44672 | E496: =TODAY() -> 46273 | F496: Touba Guédé | G496: 0.68859649 | H496: =VLOOKUP(A496,[3]Sheet1!$A:$H,8,) -> 0.6995614 | I496: =H496-G496 -> 0.010964912 | J496: =DATEDIF(D496,E496,"m") -> 52 | K496: =IF(H496="","➡️ Stable",IF(H496>0.005,"⬆️ En hausse",IF(H496<-0.005,"⬇️ En baisse","➡️ Stable"))) -> ⬆️ En hausse
... A534: O_KMR_L05 | B534: OODN | C534: DR2 | D534: 44728 | E534: =TODAY() -> 46273 | F534: Malika | G534: 0.81570513 | H534: =VLOOKUP(A534,[3]Sheet1!$A:$H,8,) -> 0.82051282 | I534: =H534-G534 -> 0.0048076923 | J534: =DATEDIF(D534,E534,"m") -> 50 | K534: =IF(H534="","➡️ Stable",IF(H534>0.005,"⬆️ En hausse",IF(H534<-0.005,"⬇️ En baisse","➡️ Stable"))) -> ⬆️ En hausse
A535: O_GDW_M16 | B535: OODN | C535: DR2 | D535: 44734 | E535: =TODAY() -> 46273 | G535: 0.69166667 | H535: =VLOOKUP(A535,[3]Sheet1!$A:$H,8,) -> 0.70166667 | I535: =H535-G535 -> 0.01 | J535: =DATEDIF(D535,E535,"m") -> 50 | K535: =IF(H535="","➡️ Stable",IF(H535>0.005,"⬆️ En hausse",IF(H535<-0.005,"⬇️ En baisse","➡️ Stable"))) -> ⬆️ En hausse
A536: O_GMB_B17 | B536: OODN | C536: DRC | D536: 44734 | E536: =TODAY() -> 46273 | G536: 0.67329545 | H536: =VLOOKUP(A536,[3]Sheet1!$A:$H,8,) -> 0.67897727 | I536: =H536-G536 -> 0.0056818182 | J536: =DATEDIF(D536,E536,"m") -> 50 | K536: =IF(H536="","➡️ Stable",IF(H536>0.005,"⬆️ En hausse",IF(H536<-0.005,"⬇️ En baisse","➡️ Stable"))) -> ⬆️ En hausse
A537: O_GMB_B27 | B537: OODN | C537: DRC | D537: 44734 | E537: =TODAY() -> 46273 | G537: 0.54896907 | H537: =VLOOKUP(A537,[3]Sheet1!$A:$H,8,) -> 0.55412371 | I537: =H537-G537 -> 0.0051546392 | J537: =DATEDIF(D537,E537,"m") -> 50 | K537: =IF(H537="","➡️ Stable",IF(H537>0.005,"⬆️ En hausse",IF(H537<-0.005,"⬇️ En baisse","➡️ Stable"))) -> ⬆️ En hausse
A538: O_CAM_H17 | B538: OODN | C538: DR2 | D538: 44739 | E538: =TODAY() -> 46273 | F538: Camberene | G538: 0.82333333 | H538: =VLOOKUP(A538,[3]Sheet1!$A:$H,8,) -> 0.83333333 | I538: =H538-G538 -> 0.01 | J538: =DATEDIF(D538,E538,"m") -> 50 | K538: =IF(H538="","➡️ Stable",IF(H538>0.005,"⬆️ En hausse",IF(H538<-0.005,"⬇️ En baisse","➡️ Stable"))) -> ⬆️ En hausse
A539: O_CAM_H51 | B539: OODN | C539: DR2 | D539: 44739 | E539: =TODAY() -> 46273 | F539: Camberene | G539: 0.7827381 | H539: =VLOOKUP(A539,[3]Sheet1!$A:$H,8,) -> 0.78720238 | I539: =H539-G539 -> 0.0044642857 | J539: =DATEDIF(D539,E539,"m") -> 50 | K539: =IF(H539="","➡️ Stable",IF(H539>0.005,"⬆️ En hausse",IF(H539<-0.005,"⬇️ En baisse","➡️ Stable"))) -> ⬆️ En hausse
A540: O_GMB_B33 | B540: OODN | C540: DRC | D540: 44739 | E540: =TODAY() -> 46273 | F540: Saly Aérodrome | G540: 0.50294118 | H540: =VLOOKUP(A540,[3]Sheet1!$A:$H,8,) -> 0.50294118 | I540: =H540-G540 -> 0 | J540: =DATEDIF(D540,E540,"m") -> 50 | K540: =IF(H540="","➡️ Stable",IF(H540>0.005,"⬆️ En hausse",IF(H540<-0.005,"⬇️ En baisse","➡️ Stable"))) -> ⬆️ En hausse
A541: O_GMB_B25 | B541: OODN | C541: DRC | D541: 44742 | E541: =TODAY() -> 46273 | F541: Grand Mbour | G541: 0.64108911 | H541: =VLOOKUP(A541,[3]Sheet1!$A:$H,8,) -> 0.63985149 | I541: =H541-G541 -> -0.0012376238 | J541: =DATEDIF(D541,E541,"m") -> 50 | K541: =IF(H541="","➡️ Stable",IF(H541>0.005,"⬆️ En hausse",IF(H541<-0.005,"⬇️ En baisse","➡️ Stable"))) -> ⬆️ En hausse
A542: O_CAM_H37 | B542: OODN | C542: DR2 | D542: 44746 | E542: =TODAY() -> 46273 | F542: Grand Médine | G542: 0.78693182 | H542: =VLOOKUP(A542,[3]Sheet1!$A:$H,8,) -> 0.79261364 | I542: =H542-G542 -> 0.0056818182 | J542: =DATEDIF(D542,E542,"m") -> 50 | K542: =IF(H542="","➡️ Stable",IF(H542>0.005,"⬆️ En hausse",IF(H542<-0.005,"⬇️ En baisse","➡️ Stable"))) -> ⬆️ En hausse
A543: O_CAM_H57 | B543: OODN | C543: DR2 | D543: 44746 | E543: =TODAY() -> 46273 | F543: Parcelle Unité 13 | G543: 0.85459184 | H543: =VLOOKUP(A543,[3]Sheet1!$A:$H,8,) -> 0.85459184 | I543: =H543-G543 -> 0 | J543: =DATEDIF(D543,E543,"m") -> 50 | K543: =IF(H543="","➡️ Stable",IF(H543>0.005,"⬆️ En hausse",IF(H543<-0.005,"⬇️ En baisse","➡️ Stable"))) -> ⬆️ En hausse
A544: O_CAM_H58 | B544: OODN | C544: DR2 | D544: 44746 | E544: =TODAY() -> 46273 | F544: Parcelle Unité 13 | G544: 0.78181818 | H544: =VLOOKUP(A544,[3]Sheet1!$A:$H,8,) -> 0.78181818 | I544: =H544-G544 -> 0 | J544: =DATEDIF(D544,E544,"m") -> 50 | K544: =IF(H544="","➡️ Stable",IF(H544>0.005,"⬆️ En hausse",IF(H544<-0.005,"⬇️ En baisse","➡️ Stable"))) -> ⬆️ En hausse
A545: O_MBW_R19 | B545: OODN | C545: DR2 | D545: 44748 | E545: =TODAY() -> 46273 | F545: Zac Mbao | G545: 0.859375 | H545: =VLOOKUP(A545,[3]Sheet1!$A:$H,8,) -> 0.859375 | I545: =H545-G545 -> 0 | J545: =DATEDIF(D545,E545,"m") -> 50 | K545: =IF(H545="","➡️ Stable",IF(H545>0.005,"⬆️ En hausse",IF(H545<-0.005,"⬇️ En baisse","➡️ Stable"))) -> ⬆️ En hausse
